<?xml version='1.0'?>
<sdf version='1.6'>
		<model name="jointtest">
			<self_collide>true</self_collide>
			<pose>0.0 0.0 0.0 0.0 0.0 0.0</pose>
			<!-- Start of parts of the pmodel jointtest -->
			<!-- End of parts of the pmodel jointtest -->
			
			<!-- Start of links of the pmodel jointtest -->
			<!-- link full name is jointtest::L1 -->
			<link name="1-L1">
					<pose>0.0 0.0 0.0 0.0 0.0 0.0</pose>
					<inertial>
						<pose>0.0 0.0 0.0 0.0 0.0 0.0</pose>
						<inertia>
							<ixx>1.0</ixx>
							<ixy>0.0</ixy>
							<ixz>0.0</ixz>
							<iyy>1.0</iyy>
							<iyz>0.0</iyz>
							<izz>1.0</izz>
						</inertia>
						<mass>1.0</mass>
					</inertial>
			</link>	
			<!-- link full name is jointtest::L2::0 -->
			<link name="2-L2">
					<pose>0.0 0.0 0.0 0.0 0.0 0.0</pose>
					<inertial>
						<pose>0.0 0.0 0.0 0.0 0.0 0.0</pose>
						<inertia>
							<ixx>1.0</ixx>
							<ixy>0.0</ixy>
							<ixz>0.0</ixz>
							<iyy>1.0</iyy>
							<iyz>0.0</iyz>
							<izz>1.0</izz>
						</inertia>
						<mass>1.0</mass>
					</inertial>
			</link>	
			<!-- link full name is jointtest::L2::1 -->
			<link name="3-L2">
					<pose>1.0 0.0 0.0 0.0 0.0 0.0</pose>
					<inertial>
						<pose>0.0 0.0 0.0 0.0 0.0 0.0</pose>
						<inertia>
							<ixx>1.0</ixx>
							<ixy>0.0</ixy>
							<ixz>0.0</ixz>
							<iyy>1.0</iyy>
							<iyz>0.0</iyz>
							<izz>1.0</izz>
						</inertia>
						<mass>1.0</mass>
					</inertial>
			</link>	
			<!-- End of links of the pmodel jointtest -->
			
			<!-- Start of joints of the pmodel jointtest -->
			<!-- Full name of joint: jointtest::L1::R from jointtest::L1 to jointtest::L2::0-->
			<joint name="4-R" type="revolute">
				<pose>0.0 0.0 0.0 0.0 -0.0 0.0</pose>
				<parent>1-L1</parent>
				<child>2-L2</child>
				<!-- WARNING: The SDF generator relies on annotations of the joint 4-R to specify in SDF aspects of the joint that are
					 accounted for in the equations. -->
				<axis>
					<xyz>0 0 1</xyz>
				</axis>
			</joint>
			<!-- Full name of joint: jointtest::L1::R from jointtest::L1 to jointtest::L2::1-->
			<joint name="5-R" type="revolute">
				<pose>-1.0 0.0 0.0 0.0 -0.0 0.0</pose>
				<parent>1-L1</parent>
				<child>3-L2</child>
				<!-- WARNING: The SDF generator relies on annotations of the joint 5-R to specify in SDF aspects of the joint that are
					 accounted for in the equations. -->
				<axis>
					<xyz>0 0 1</xyz>
				</axis>
			</joint>
			<!-- End of joints of the pmodel jointtest -->
			
			<!-- Start of fixed connections of the pmodel jointtest -->
			<!-- End of fixed connections of the pmodel jointtest -->
		</model>
</sdf>
