<?xml version='1.0'?>
<sdf version='1.6'>
		<model name="jointtest">
			<self_collide>true</self_collide>
			<pose>0.0 0.0 0.0 0.0 0.0 0.0</pose>
			<!-- Start of parts of the pmodel jointtest -->
				<!-- Start of declarations for part "jointtest::p" -->
					<!-- Start of parts of part "jointtest::p" -->
					<!-- End of parts of part "jointtest::p" -->
					
					<!-- Start of links of part "jointtest::p" -->
					<!-- link full name is jointtest::p::L2 -->
					<link name="1-L2">
							<pose>1.0 0.0 0.0 0.0 0.0 0.0</pose>
							<inertial>
								<pose>0.0 0.0 0.0 0.0 0.0 0.0</pose>
								<inertia>
									<ixx>1.0</ixx>
									<ixy>0.0</ixy>
									<ixz>0.0</ixz>
									<iyy>1.0</iyy>
									<iyz>0.0</iyz>
									<izz>1.0</izz>
								</inertia>
								<mass>1.0</mass>
							</inertial>
					</link>	
					<!-- End of links of part "jointtest::p" -->
					
					<!-- Start of joints of part "jointtest::p" -->
					<!-- End of joints of part "jointtest::p" -->
					
					<!-- Start of fixed connections of part "jointtest::p" -->
					
					<!-- End of fixed connections of part "jointtest::p" -->
				<!-- End of declarations for part "jointtest::p" -->
			<!-- End of parts of the pmodel jointtest -->
			
			<!-- Start of links of the pmodel jointtest -->
			<!-- link full name is jointtest::L1 -->
			<link name="2-L1">
					<pose>0.0 0.0 0.0 0.0 0.0 0.0</pose>
					<inertial>
						<pose>0.0 0.0 0.0 0.0 0.0 0.0</pose>
						<inertia>
							<ixx>1.0</ixx>
							<ixy>0.0</ixy>
							<ixz>0.0</ixz>
							<iyy>1.0</iyy>
							<iyz>0.0</iyz>
							<izz>1.0</izz>
						</inertia>
						<mass>1.0</mass>
					</inertial>
			</link>	
			<!-- End of links of the pmodel jointtest -->
			
			<!-- Start of joints of the pmodel jointtest -->
			<!-- Full name of joint: jointtest::L1::R from jointtest::L1 to jointtest::p::L2-->
			<joint name="3-R" type="revolute">
				<pose>-1.0 0.0 0.0 0.0 -0.0 0.0</pose>
				<parent>2-L1</parent>
				<child>1-L2</child>
				<!-- WARNING: The SDF generator relies on annotations of the joint 3-R to specify in SDF aspects of the joint that are
					 accounted for in the equations. -->
				<axis>
					<xyz>0 0 1</xyz>
				</axis>
			</joint>
			<!-- End of joints of the pmodel jointtest -->
			
			<!-- Start of fixed connections of the pmodel jointtest -->
			<!-- End of fixed connections of the pmodel jointtest -->
		</model>
</sdf>
