<?xml version='1.0'?>
<sdf version='1.6'>
		<model name="testflexible">
			<self_collide>true</self_collide>
			<pose>0.0 0.0 0.0 0.0 0.0 0.0</pose>
			<!-- Start of parts of the pmodel testflexible -->
				<!-- Start of declarations for part "testflexible::TESTLINK" -->
					<!-- Start of parts of part "testflexible::TESTLINK" -->
					<!-- End of parts of part "testflexible::TESTLINK" -->
					
					<!-- Start of links of part "testflexible::TESTLINK" -->
					<!-- link full name is testflexible::TESTLINK::L2 -->
					<link name="1-L2">
							<pose>0.0 0.0 0.10000000149011612 0.0 0.0 0.0</pose>
							<inertial>
								<pose>0.0 0.0 0.0 0.0 0.0 0.0</pose>
								<inertia>
									<ixx>1.0</ixx>
									<ixy>0.0</ixy>
									<ixz>0.0</ixz>
									<iyy>1.0</iyy>
									<iyz>0.0</iyz>
									<izz>1.0</izz>
								</inertia>
								<mass>1.0</mass>
							</inertial>
							<!-- body full name is testflexible::TESTLINK::L2::B2 -->
							<collision name="1--B2">
								<laser_retro>0.0</laser_retro>
								<pose>0.0 0.0 0.0 0.0 0.0 0.0</pose>
								<geometry>
									<box> 
										<size>0.10000000149011612 0.10000000149011612 0.10000000149011612</size>
									</box>
								</geometry>
								<surface>
									<bounce>
										<restitution_coefficient>0.0</restitution_coefficient>
										<threshold>100000.0</threshold>
									</bounce>
									<friction>
										<ode>
											<mu>1.0</mu>
											<mu2>1.0</mu2>
											<fdir1>0.0 0.0 0.0</fdir1>
											<slip1>0.0</slip1>
											<slip2>0.0</slip2>
										</ode>
										<torsional>
											<coefficient>1.0</coefficient>
											<surface_radius>0.0</surface_radius>
										</torsional>
									</friction>
								</surface>
							</collision>
							<visual name="1--B2">
								<laser_retro>0.0</laser_retro>
								<pose>0.0 0.0 0.0 0.0 0.0 0.0</pose>
								<geometry>
									<box> 
										<size>0.10000000149011612 0.10000000149011612 0.10000000149011612</size>
									</box>
								</geometry>
								<surface>
									<bounce>
										<restitution_coefficient>0.0</restitution_coefficient>
										<threshold>100000.0</threshold>
									</bounce>
									<friction>
										<ode>
											<mu>1.0</mu>
											<mu2>1.0</mu2>
											<fdir1>0.0 0.0 0.0</fdir1>
											<slip1>0.0</slip1>
											<slip2>0.0</slip2>
										</ode>
										<torsional>
											<coefficient>1.0</coefficient>
											<surface_radius>0.0</surface_radius>
										</torsional>
									</friction>
								</surface>
							</visual>
					</link>	
					<!-- End of links of part "testflexible::TESTLINK" -->
					
					<!-- Start of joints of part "testflexible::TESTLINK" -->
					<!-- End of joints of part "testflexible::TESTLINK" -->
					
					<!-- Start of fixed connections of part "testflexible::TESTLINK" -->
					
					<!-- End of fixed connections of part "testflexible::TESTLINK" -->
				<!-- End of declarations for part "testflexible::TESTLINK" -->
			<!-- End of parts of the pmodel testflexible -->
			
			<!-- Start of links of the pmodel testflexible -->
			<!-- link full name is testflexible::L1 -->
			<link name="2-L1">
					<pose>0.0 0.0 0.05000000074505806 0.0 0.0 0.0</pose>
					<inertial>
						<pose>0.0 0.0 0.0 0.0 0.0 0.0</pose>
						<inertia>
							<ixx>1.0</ixx>
							<ixy>0.0</ixy>
							<ixz>0.0</ixz>
							<iyy>1.0</iyy>
							<iyz>0.0</iyz>
							<izz>1.0</izz>
						</inertia>
						<mass>1.0</mass>
					</inertial>
					<!-- body full name is testflexible::L1::B1 -->
					<collision name="2--B1">
						<laser_retro>0.0</laser_retro>
						<pose>0.0 0.0 0.0 0.0 0.0 0.0</pose>
						<geometry>
							<box> 
								<size>0.10000000149011612 0.10000000149011612 0.10000000149011612</size>
							</box>
						</geometry>
						<surface>
							<bounce>
								<restitution_coefficient>0.0</restitution_coefficient>
								<threshold>100000.0</threshold>
							</bounce>
							<friction>
								<ode>
									<mu>1.0</mu>
									<mu2>1.0</mu2>
									<fdir1>0.0 0.0 0.0</fdir1>
									<slip1>0.0</slip1>
									<slip2>0.0</slip2>
								</ode>
								<torsional>
									<coefficient>1.0</coefficient>
									<surface_radius>0.0</surface_radius>
								</torsional>
							</friction>
						</surface>
					</collision>
					<visual name="2--B1">
						<laser_retro>0.0</laser_retro>
						<pose>0.0 0.0 0.0 0.0 0.0 0.0</pose>
						<geometry>
							<box> 
								<size>0.10000000149011612 0.10000000149011612 0.10000000149011612</size>
							</box>
						</geometry>
						<surface>
							<bounce>
								<restitution_coefficient>0.0</restitution_coefficient>
								<threshold>100000.0</threshold>
							</bounce>
							<friction>
								<ode>
									<mu>1.0</mu>
									<mu2>1.0</mu2>
									<fdir1>0.0 0.0 0.0</fdir1>
									<slip1>0.0</slip1>
									<slip2>0.0</slip2>
								</ode>
								<torsional>
									<coefficient>1.0</coefficient>
									<surface_radius>0.0</surface_radius>
								</torsional>
							</friction>
						</surface>
					</visual>
			</link>	
			<!-- End of links of the pmodel testflexible -->
			
			<!-- Start of joints of the pmodel testflexible -->
			<!-- Full name of joint: testflexible::L1::R from testflexible::L1 to testflexible::TESTLINK::L2-->
			<joint name="3-R" type="revolute">
				<pose>0.0 0.0 -0.05000000074505806 0.0 -0.0 0.0</pose>
				<parent>2-L1</parent>
				<child>1-L2</child>
				<!-- WARNING: Annotation not found for the joint 3-R. The SDF generator relies on annotations to specify SDF aspects
				     of the joint that are accounted for in the equations. If you wish to reflect these aspects in SDF,
				     please add an appropriate annotation to the joint. --> 
			</joint>
			<!-- End of joints of the pmodel testflexible -->
			
			<!-- Start of fixed connections of the pmodel testflexible -->
			<!-- End of fixed connections of the pmodel testflexible -->
		</model>
</sdf>
