<?xml version='1.0'?>
<sdf version='1.6'>
		<model name="TwoBodiesPlusRevoluteJoint">
			<self_collide>true</self_collide>
			<pose>0.0 0.0 0.0 0.0 0.0 0.0</pose>
			<!-- Start of parts of the pmodel TwoBodiesPlusRevoluteJoint -->
			<!-- End of parts of the pmodel TwoBodiesPlusRevoluteJoint -->
			
			<!-- Start of links of the pmodel TwoBodiesPlusRevoluteJoint -->
			<!-- link full name is TwoBodiesPlusRevoluteJoint::base_link -->
			<link name="1-base_link">
					<pose>0.0 0.0 0.0 0.0 0.0 0.0</pose>
					<inertial>
						<pose>0.0 0.0 0.0 0.0 0.0 0.0</pose>
						<inertia>
							<ixx>0.4000000059604645</ixx>
							<ixy>0.0</ixy>
							<ixz>0.0</ixz>
							<iyy>0.4000000059604645</iyy>
							<iyz>0.0</iyz>
							<izz>0.20000000298023224</izz>
						</inertia>
						<mass>10.0</mass>
					</inertial>
					<!-- body full name is TwoBodiesPlusRevoluteJoint::base_link::base_body -->
					<collision name="1--base_body">
						<laser_retro>0.0</laser_retro>
						<pose>0.0 0.0 0.0 0.0 0.0 0.0</pose>
						<geometry>
							<cylinder>
								<radius>0.05000000074505806</radius>
								<length>0.23999999463558197</length>
							</cylinder>
						</geometry>
						<surface>
							<bounce>
								<restitution_coefficient>0.0</restitution_coefficient>
								<threshold>100000.0</threshold>
							</bounce>
							<friction>
								<ode>
									<mu>1.0</mu>
									<mu2>1.0</mu2>
									<fdir1>0.0 0.0 0.0</fdir1>
									<slip1>0.0</slip1>
									<slip2>0.0</slip2>
								</ode>
								<torsional>
									<coefficient>1.0</coefficient>
									<surface_radius>0.0</surface_radius>
								</torsional>
							</friction>
						</surface>
					</collision>
					<visual name="1--base_body">
						<laser_retro>0.0</laser_retro>
						<pose>0.0 0.0 0.0 0.0 0.0 0.0</pose>
						<geometry>
							<cylinder>
								<radius>0.05000000074505806</radius>
								<length>0.23999999463558197</length>
							</cylinder>
						</geometry>
						<surface>
							<bounce>
								<restitution_coefficient>0.0</restitution_coefficient>
								<threshold>100000.0</threshold>
							</bounce>
							<friction>
								<ode>
									<mu>1.0</mu>
									<mu2>1.0</mu2>
									<fdir1>0.0 0.0 0.0</fdir1>
									<slip1>0.0</slip1>
									<slip2>0.0</slip2>
								</ode>
								<torsional>
									<coefficient>1.0</coefficient>
									<surface_radius>0.0</surface_radius>
								</torsional>
							</friction>
						</surface>
					</visual>
			</link>	
			<!-- link full name is TwoBodiesPlusRevoluteJoint::second_link -->
			<link name="2-second_link">
					<pose>0.0 0.0 0.11999999731779099 0.0 0.0 0.0</pose>
					<inertial>
						<pose>0.0 0.0 0.0 0.0 0.0 0.0</pose>
						<inertia>
							<ixx>0.0</ixx>
							<ixy>2.835000050254166E-4</ixy>
							<ixz>0.0</ixz>
							<iyy>2.835000050254166E-4</iyy>
							<iyz>0.0</iyz>
							<izz>3.239999932702631E-4</izz>
						</inertia>
						<mass>10.0</mass>
					</inertial>
					<!-- body full name is TwoBodiesPlusRevoluteJoint::second_link::second_body -->
					<collision name="2--second_body">
						<laser_retro>0.0</laser_retro>
						<pose>0.0 0.0 0.0 0.0 0.0 0.0</pose>
						<geometry>
							<cylinder>
								<radius>0.029999999329447746</radius>
								<length>0.23999999463558197</length>
							</cylinder>
						</geometry>
						<surface>
							<bounce>
								<restitution_coefficient>0.0</restitution_coefficient>
								<threshold>100000.0</threshold>
							</bounce>
							<friction>
								<ode>
									<mu>1.0</mu>
									<mu2>1.0</mu2>
									<fdir1>0.0 0.0 0.0</fdir1>
									<slip1>0.0</slip1>
									<slip2>0.0</slip2>
								</ode>
								<torsional>
									<coefficient>1.0</coefficient>
									<surface_radius>0.0</surface_radius>
								</torsional>
							</friction>
						</surface>
					</collision>
					<visual name="2--second_body">
						<laser_retro>0.0</laser_retro>
						<pose>0.0 0.0 0.0 0.0 0.0 0.0</pose>
						<geometry>
							<cylinder>
								<radius>0.029999999329447746</radius>
								<length>0.23999999463558197</length>
							</cylinder>
						</geometry>
						<surface>
							<bounce>
								<restitution_coefficient>0.0</restitution_coefficient>
								<threshold>100000.0</threshold>
							</bounce>
							<friction>
								<ode>
									<mu>1.0</mu>
									<mu2>1.0</mu2>
									<fdir1>0.0 0.0 0.0</fdir1>
									<slip1>0.0</slip1>
									<slip2>0.0</slip2>
								</ode>
								<torsional>
									<coefficient>1.0</coefficient>
									<surface_radius>0.0</surface_radius>
								</torsional>
							</friction>
						</surface>
					</visual>
			</link>	
			<!-- End of links of the pmodel TwoBodiesPlusRevoluteJoint -->
			
			<!-- Start of joints of the pmodel TwoBodiesPlusRevoluteJoint -->
			<!-- Full name of joint: TwoBodiesPlusRevoluteJoint::base_link::my_revolute_joint from TwoBodiesPlusRevoluteJoint::base_link to TwoBodiesPlusRevoluteJoint::second_link-->
			<joint name="3-my_revolute_joint" type="revolute">
				<pose>0.0 0.0 0.0 0.0 -0.0 0.0</pose>
				<parent>1-base_link</parent>
				<child>2-second_link</child>
				<!-- WARNING: The SDF generator relies on annotations of the joint 3-my_revolute_joint to specify in SDF aspects of the joint that are
					 accounted for in the equations. -->
				<axis>
					<xyz>0 0 1</xyz>
					<initial_position>0.009999999776482582</initial_position>
					<dynamics>
						<damping>0.10000000149011612</damping>
						<friction>0.10000000149011612</friction>
						<spring_reference>0.10000000149011612</spring_reference>
						<spring_stiffness>0.10000000149011612</spring_stiffness>
					</dynamics>
					<limit>
						<lower>-0.10000000149011612</lower>
						<upper>2.0</upper>
						<effort>1.100000023841858</effort>
						<velocity>-1.2000000476837158</velocity>
						<stiffness>1.2999999523162842</stiffness>
						<dissipation>1.399999976158142</dissipation>
					</limit>
				</axis>
			</joint>
			<!-- End of joints of the pmodel TwoBodiesPlusRevoluteJoint -->
			
			<!-- Start of fixed connections of the pmodel TwoBodiesPlusRevoluteJoint -->
			<!-- End of fixed connections of the pmodel TwoBodiesPlusRevoluteJoint -->
		</model>
</sdf>
