<?xml version='1.0'?>
<sdf version='1.6'>
		<model name="A">
			<self_collide>true</self_collide>
			<pose>0.0 0.0 0.0 0.0 0.0 0.0</pose>
			<!-- Start of parts of the pmodel A -->
			<!-- End of parts of the pmodel A -->
			
			<!-- Start of links of the pmodel A -->
			<!-- link full name is A::L1 -->
			<link name="1-L1">
					<pose>0.0 0.0 0.05000000074505806 0.0 0.0 0.0</pose>
					<inertial>
						<pose>0.0 0.0 0.0 0.0 0.0 0.0</pose>
						<inertia>
							<ixx>1.0</ixx>
							<ixy>0.0</ixy>
							<ixz>0.0</ixz>
							<iyy>1.0</iyy>
							<iyz>0.0</iyz>
							<izz>1.0</izz>
						</inertia>
						<mass>1.0</mass>
					</inertial>
					<!-- body full name is A::L1::B1 -->
					<collision name="1--B1">
						<laser_retro>0.0</laser_retro>
						<pose>0.0 0.0 0.0 0.0 0.0 0.0</pose>
						<geometry>
							<box> 
								<size>0.10000000149011612 0.10000000149011612 0.10000000149011612</size>
							</box>
						</geometry>
						<surface>
							<bounce>
								<restitution_coefficient>0.0</restitution_coefficient>
								<threshold>100000.0</threshold>
							</bounce>
							<friction>
								<ode>
									<mu>1.0</mu>
									<mu2>1.0</mu2>
									<fdir1>0.0 0.0 0.0</fdir1>
									<slip1>0.0</slip1>
									<slip2>0.0</slip2>
								</ode>
								<torsional>
									<coefficient>1.0</coefficient>
									<surface_radius>0.0</surface_radius>
								</torsional>
							</friction>
						</surface>
					</collision>
					<visual name="1--B1">
						<laser_retro>0.0</laser_retro>
						<pose>0.0 0.0 0.0 0.0 0.0 0.0</pose>
						<geometry>
							<box> 
								<size>0.10000000149011612 0.10000000149011612 0.10000000149011612</size>
							</box>
						</geometry>
						<surface>
							<bounce>
								<restitution_coefficient>0.0</restitution_coefficient>
								<threshold>100000.0</threshold>
							</bounce>
							<friction>
								<ode>
									<mu>1.0</mu>
									<mu2>1.0</mu2>
									<fdir1>0.0 0.0 0.0</fdir1>
									<slip1>0.0</slip1>
									<slip2>0.0</slip2>
								</ode>
								<torsional>
									<coefficient>1.0</coefficient>
									<surface_radius>0.0</surface_radius>
								</torsional>
							</friction>
						</surface>
					</visual>
					<!-- WARNING: RoboSim actuators have no explicit counterparts in SDF, so the generator must rely on
						 annotations to produce something meaningful in SDF for the actuator A. -->
					<!-- actuator simple name is A -->
					<light name="A">
					</light>
			</link>	
			<!-- link full name is A::L2 -->
			<link name="2-L2">
					<pose>0.0 0.0 0.10000000149011612 0.0 0.0 0.0</pose>
					<inertial>
						<pose>0.0 0.0 0.0 0.0 0.0 0.0</pose>
						<inertia>
							<ixx>1.0</ixx>
							<ixy>0.0</ixy>
							<ixz>0.0</ixz>
							<iyy>1.0</iyy>
							<iyz>0.0</iyz>
							<izz>1.0</izz>
						</inertia>
						<mass>1.0</mass>
					</inertial>
					<!-- body full name is A::L2::B2 -->
					<collision name="2--B2">
						<laser_retro>0.0</laser_retro>
						<pose>0.0 0.0 0.0 0.0 0.0 0.0</pose>
						<geometry>
							<box> 
								<size>0.10000000149011612 0.10000000149011612 0.10000000149011612</size>
							</box>
						</geometry>
						<surface>
							<bounce>
								<restitution_coefficient>0.0</restitution_coefficient>
								<threshold>100000.0</threshold>
							</bounce>
							<friction>
								<ode>
									<mu>1.0</mu>
									<mu2>1.0</mu2>
									<fdir1>0.0 0.0 0.0</fdir1>
									<slip1>0.0</slip1>
									<slip2>0.0</slip2>
								</ode>
								<torsional>
									<coefficient>1.0</coefficient>
									<surface_radius>0.0</surface_radius>
								</torsional>
							</friction>
						</surface>
					</collision>
					<visual name="2--B2">
						<laser_retro>0.0</laser_retro>
						<pose>0.0 0.0 0.0 0.0 0.0 0.0</pose>
						<geometry>
							<box> 
								<size>0.10000000149011612 0.10000000149011612 0.10000000149011612</size>
							</box>
						</geometry>
						<surface>
							<bounce>
								<restitution_coefficient>0.0</restitution_coefficient>
								<threshold>100000.0</threshold>
							</bounce>
							<friction>
								<ode>
									<mu>1.0</mu>
									<mu2>1.0</mu2>
									<fdir1>0.0 0.0 0.0</fdir1>
									<slip1>0.0</slip1>
									<slip2>0.0</slip2>
								</ode>
								<torsional>
									<coefficient>1.0</coefficient>
									<surface_radius>0.0</surface_radius>
								</torsional>
							</friction>
						</surface>
					</visual>
			</link>	
			<!-- End of links of the pmodel A -->
			
			<!-- Start of joints of the pmodel A -->
			<!-- Full name of joint: A::L1::R from A::L1 to A::L2-->
			<joint name="3-R" type="revolute">
				<pose>0.0 0.0 -0.05000000074505806 0.0 -0.0 0.0</pose>
				<parent>1-L1</parent>
				<child>2-L2</child>
				<!-- WARNING: Annotation not found for the joint 3-R. The SDF generator relies on annotations to specify SDF aspects
				     of the joint that are accounted for in the equations. If you wish to reflect these aspects in SDF,
				     please add an appropriate annotation to the joint. --> 
				<!-- WARNING: RoboSim actuators have no explicit counterparts in SDF, so the generator must rely on
					 annotations to produce something meaningful in SDF for the actuator Motor. -->
				<!-- actuator simple name is Motor -->
				<physics name="Motor">
				</physics>
			</joint>
			<!-- End of joints of the pmodel A -->
			
			<!-- Start of fixed connections of the pmodel A -->
			<!-- End of fixed connections of the pmodel A -->
		</model>
</sdf>
