<?xml version='1.0'?>
<sdf version='1.6'>
		<model name="testflexible">
			<self_collide>true</self_collide>
			<pose>0.0 0.0 0.0 0.0 0.0 0.0</pose>
			<!-- Start of parts of the pmodel testflexible -->
				<!-- Start of declarations for part "testflexible::TP" -->
					<!-- Start of parts of part "testflexible::TP" -->
					<!-- End of parts of part "testflexible::TP" -->
					
					<!-- Start of links of part "testflexible::TP" -->
					<!-- link full name is testflexible::TP::linkB -->
					<link name="1-linkB">
							<pose>0.0 -0.5 0.5 1.0471999645233154 -0.785398006439209 1.0471999645233154</pose>
							<inertial>
								<pose>0.0 0.0 0.0 0.0 0.0 0.0</pose>
								<inertia>
									<ixx>1.0</ixx>
									<ixy>0.0</ixy>
									<ixz>0.0</ixz>
									<iyy>1.0</iyy>
									<iyz>0.0</iyz>
									<izz>1.0</izz>
								</inertia>
								<mass>1.0</mass>
							</inertial>
							<!-- body full name is testflexible::TP::linkB::bodyB -->
							<collision name="1--bodyB">
								<laser_retro>0.0</laser_retro>
								<pose>0.0 0.0 0.0 0.0 0.0 0.0</pose>
								<geometry>
									<box> 
										<size>1.0 1.0 1.0</size>
									</box>
								</geometry>
								<surface>
									<bounce>
										<restitution_coefficient>0.0</restitution_coefficient>
										<threshold>100000.0</threshold>
									</bounce>
									<friction>
										<ode>
											<mu>1.0</mu>
											<mu2>1.0</mu2>
											<fdir1>0.0 0.0 0.0</fdir1>
											<slip1>0.0</slip1>
											<slip2>0.0</slip2>
										</ode>
										<torsional>
											<coefficient>1.0</coefficient>
											<surface_radius>0.0</surface_radius>
										</torsional>
									</friction>
								</surface>
							</collision>
							<visual name="1--bodyB">
								<laser_retro>0.0</laser_retro>
								<pose>0.0 0.0 0.0 0.0 0.0 0.0</pose>
								<geometry>
									<box> 
										<size>1.0 1.0 1.0</size>
									</box>
								</geometry>
								<surface>
									<bounce>
										<restitution_coefficient>0.0</restitution_coefficient>
										<threshold>100000.0</threshold>
									</bounce>
									<friction>
										<ode>
											<mu>1.0</mu>
											<mu2>1.0</mu2>
											<fdir1>0.0 0.0 0.0</fdir1>
											<slip1>0.0</slip1>
											<slip2>0.0</slip2>
										</ode>
										<torsional>
											<coefficient>1.0</coefficient>
											<surface_radius>0.0</surface_radius>
										</torsional>
									</friction>
								</surface>
							</visual>
					</link>	
					<!-- End of links of part "testflexible::TP" -->
					
					<!-- Start of joints of part "testflexible::TP" -->
					<!-- Full name of joint: testflexible::TP::linkB::barAB_joint from testflexible::TP::linkB to testflexible::linkA-->
					<joint name="3-barAB_joint" type="revolute">
						<pose>-0.42943818876124323 0.30619131382942966 0.9758582576874864 0.1417752224396361 -0.12717128718089174 0.3644447912150492</pose>
						<parent>1-linkB</parent>
						<child>2-linkA</child>
						<!-- WARNING: The SDF generator relies on annotations of the joint 3-barAB_joint to specify in SDF aspects of the joint that are
							 accounted for in the equations. -->
						<axis>
							<xyz>0 0 1</xyz>
						</axis>
					</joint>
					<!-- End of joints of part "testflexible::TP" -->
					
					<!-- Start of fixed connections of part "testflexible::TP" -->
					
					<!-- End of fixed connections of part "testflexible::TP" -->
				<!-- End of declarations for part "testflexible::TP" -->
			<!-- End of parts of the pmodel testflexible -->
			
			<!-- Start of links of the pmodel testflexible -->
			<!-- link full name is testflexible::linkA -->
			<link name="2-linkA">
					<pose>1.0 0.5 0.5 1.5707999467849731 3.141590118408203 -1.0471999645233154</pose>
					<inertial>
						<pose>0.0 0.0 0.0 0.0 0.0 0.0</pose>
						<inertia>
							<ixx>1.0</ixx>
							<ixy>0.0</ixy>
							<ixz>0.0</ixz>
							<iyy>1.0</iyy>
							<iyz>0.0</iyz>
							<izz>1.0</izz>
						</inertia>
						<mass>1.0</mass>
					</inertial>
					<!-- body full name is testflexible::linkA::bodyA -->
					<collision name="2--bodyA">
						<laser_retro>0.0</laser_retro>
						<pose>0.0 0.0 0.0 0.0 0.0 0.0</pose>
						<geometry>
							<box> 
								<size>1.0 1.0 1.0</size>
							</box>
						</geometry>
						<surface>
							<bounce>
								<restitution_coefficient>0.0</restitution_coefficient>
								<threshold>100000.0</threshold>
							</bounce>
							<friction>
								<ode>
									<mu>1.0</mu>
									<mu2>1.0</mu2>
									<fdir1>0.0 0.0 0.0</fdir1>
									<slip1>0.0</slip1>
									<slip2>0.0</slip2>
								</ode>
								<torsional>
									<coefficient>1.0</coefficient>
									<surface_radius>0.0</surface_radius>
								</torsional>
							</friction>
						</surface>
					</collision>
					<visual name="2--bodyA">
						<laser_retro>0.0</laser_retro>
						<pose>0.0 0.0 0.0 0.0 0.0 0.0</pose>
						<geometry>
							<box> 
								<size>1.0 1.0 1.0</size>
							</box>
						</geometry>
						<surface>
							<bounce>
								<restitution_coefficient>0.0</restitution_coefficient>
								<threshold>100000.0</threshold>
							</bounce>
							<friction>
								<ode>
									<mu>1.0</mu>
									<mu2>1.0</mu2>
									<fdir1>0.0 0.0 0.0</fdir1>
									<slip1>0.0</slip1>
									<slip2>0.0</slip2>
								</ode>
								<torsional>
									<coefficient>1.0</coefficient>
									<surface_radius>0.0</surface_radius>
								</torsional>
							</friction>
						</surface>
					</visual>
			</link>	
			<!-- End of links of the pmodel testflexible -->
			
			<!-- Start of joints of the pmodel testflexible -->
			<!-- End of joints of the pmodel testflexible -->
			
			<!-- Start of fixed connections of the pmodel testflexible -->
			<!-- End of fixed connections of the pmodel testflexible -->
		</model>
</sdf>
