<?xml version='1.0'?>
<sdf version='1.6'>
		<model name="Base">
			<self_collide>true</self_collide>
			<pose>0.0 0.0 0.0 0.0 0.0 0.0</pose>
			<!-- Start of parts of the pmodel Base -->
				<!-- Start of declarations for part "Base::LWHEEL" -->
					<!-- Start of parts of part "Base::LWHEEL" -->
					<!-- End of parts of part "Base::LWHEEL" -->
					
					<!-- Start of links of part "Base::LWHEEL" -->
					<!-- link full name is Base::LWHEEL::wheel -->
					<link name="1-wheel">
							<pose>-0.10000000149011612 0.0 0.0 0.0 0.0 0.0</pose>
							<inertial>
								<pose>0.0 0.0 0.0 0.0 0.0 0.0</pose>
								<inertia>
									<ixx>1.0</ixx>
									<ixy>0.0</ixy>
									<ixz>0.0</ixz>
									<iyy>1.0</iyy>
									<iyz>0.0</iyz>
									<izz>1.0</izz>
								</inertia>
								<mass>1.0</mass>
							</inertial>
							<!-- body full name is Base::LWHEEL::wheel::bwheel -->
							<collision name="1--bwheel">
								<laser_retro>0.0</laser_retro>
								<pose>0.0 0.0 0.0 0.0 0.0 0.0</pose>
								<geometry>
									<cylinder>
										<radius>0.02500000037252903</radius>
										<length>0.029999999329447746</length>
									</cylinder>
								</geometry>
								<surface>
									<bounce>
										<restitution_coefficient>0.0</restitution_coefficient>
										<threshold>100000.0</threshold>
									</bounce>
									<friction>
										<ode>
											<mu>1.0</mu>
											<mu2>1.0</mu2>
											<fdir1>0.0 0.0 0.0</fdir1>
											<slip1>0.0</slip1>
											<slip2>0.0</slip2>
										</ode>
										<torsional>
											<coefficient>1.0</coefficient>
											<surface_radius>0.0</surface_radius>
										</torsional>
									</friction>
								</surface>
							</collision>
							<visual name="1--bwheel">
								<laser_retro>0.0</laser_retro>
								<pose>0.0 0.0 0.0 0.0 0.0 0.0</pose>
								<geometry>
									<cylinder>
										<radius>0.02500000037252903</radius>
										<length>0.029999999329447746</length>
									</cylinder>
								</geometry>
								<surface>
									<bounce>
										<restitution_coefficient>0.0</restitution_coefficient>
										<threshold>100000.0</threshold>
									</bounce>
									<friction>
										<ode>
											<mu>1.0</mu>
											<mu2>1.0</mu2>
											<fdir1>0.0 0.0 0.0</fdir1>
											<slip1>0.0</slip1>
											<slip2>0.0</slip2>
										</ode>
										<torsional>
											<coefficient>1.0</coefficient>
											<surface_radius>0.0</surface_radius>
										</torsional>
									</friction>
								</surface>
							</visual>
					</link>	
					<!-- End of links of part "Base::LWHEEL" -->
					
					<!-- Start of joints of part "Base::LWHEEL" -->
					<!-- End of joints of part "Base::LWHEEL" -->
					
					<!-- Start of fixed connections of part "Base::LWHEEL" -->
					
					<!-- End of fixed connections of part "Base::LWHEEL" -->
				<!-- End of declarations for part "Base::LWHEEL" -->
				<!-- Start of declarations for part "Base::RWHEEL" -->
					<!-- Start of parts of part "Base::RWHEEL" -->
					<!-- End of parts of part "Base::RWHEEL" -->
					
					<!-- Start of links of part "Base::RWHEEL" -->
					<!-- link full name is Base::RWHEEL::wheel -->
					<link name="2-wheel">
							<pose>0.10000000149011612 0.0 0.0 0.0 0.0 0.0</pose>
							<inertial>
								<pose>0.0 0.0 0.0 0.0 0.0 0.0</pose>
								<inertia>
									<ixx>1.0</ixx>
									<ixy>0.0</ixy>
									<ixz>0.0</ixz>
									<iyy>1.0</iyy>
									<iyz>0.0</iyz>
									<izz>1.0</izz>
								</inertia>
								<mass>1.0</mass>
							</inertial>
							<!-- body full name is Base::RWHEEL::wheel::bwheel -->
							<collision name="2--bwheel">
								<laser_retro>0.0</laser_retro>
								<pose>0.0 0.0 0.0 0.0 0.0 0.0</pose>
								<geometry>
									<cylinder>
										<radius>0.02500000037252903</radius>
										<length>0.029999999329447746</length>
									</cylinder>
								</geometry>
								<surface>
									<bounce>
										<restitution_coefficient>0.0</restitution_coefficient>
										<threshold>100000.0</threshold>
									</bounce>
									<friction>
										<ode>
											<mu>1.0</mu>
											<mu2>1.0</mu2>
											<fdir1>0.0 0.0 0.0</fdir1>
											<slip1>0.0</slip1>
											<slip2>0.0</slip2>
										</ode>
										<torsional>
											<coefficient>1.0</coefficient>
											<surface_radius>0.0</surface_radius>
										</torsional>
									</friction>
								</surface>
							</collision>
							<visual name="2--bwheel">
								<laser_retro>0.0</laser_retro>
								<pose>0.0 0.0 0.0 0.0 0.0 0.0</pose>
								<geometry>
									<cylinder>
										<radius>0.02500000037252903</radius>
										<length>0.029999999329447746</length>
									</cylinder>
								</geometry>
								<surface>
									<bounce>
										<restitution_coefficient>0.0</restitution_coefficient>
										<threshold>100000.0</threshold>
									</bounce>
									<friction>
										<ode>
											<mu>1.0</mu>
											<mu2>1.0</mu2>
											<fdir1>0.0 0.0 0.0</fdir1>
											<slip1>0.0</slip1>
											<slip2>0.0</slip2>
										</ode>
										<torsional>
											<coefficient>1.0</coefficient>
											<surface_radius>0.0</surface_radius>
										</torsional>
									</friction>
								</surface>
							</visual>
					</link>	
					<!-- End of links of part "Base::RWHEEL" -->
					
					<!-- Start of joints of part "Base::RWHEEL" -->
					<!-- End of joints of part "Base::RWHEEL" -->
					
					<!-- Start of fixed connections of part "Base::RWHEEL" -->
					
					<!-- End of fixed connections of part "Base::RWHEEL" -->
				<!-- End of declarations for part "Base::RWHEEL" -->
			<!-- End of parts of the pmodel Base -->
			
			<!-- Start of links of the pmodel Base -->
			<!-- link full name is Base::Core -->
			<link name="3-Core">
					<pose>0.0 0.0 0.0 0.0 0.0 0.0</pose>
					<inertial>
						<pose>0.0 0.0 0.0 0.0 0.0 0.0</pose>
						<inertia>
							<ixx>1.0</ixx>
							<ixy>0.0</ixy>
							<ixz>0.0</ixz>
							<iyy>1.0</iyy>
							<iyz>0.0</iyz>
							<izz>1.0</izz>
						</inertia>
						<mass>1.0</mass>
					</inertial>
			</link>	
			<!-- End of links of the pmodel Base -->
			
			<!-- Start of joints of the pmodel Base -->
			<!-- Full name of joint: Base::Core::LJ from Base::Core to Base::LWHEEL::wheel-->
			<joint name="4-LJ" type="revolute">
				<pose>0.10000000149011612 0.0 0.0 0.0 -0.0 0.0</pose>
				<parent>3-Core</parent>
				<child>1-wheel</child>
				<!-- WARNING: The SDF generator relies on annotations of the joint 4-LJ to specify in SDF aspects of the joint that are
					 accounted for in the equations. -->
			</joint>
			<!-- Full name of joint: Base::Core::RJ from Base::Core to Base::RWHEEL::wheel-->
			<joint name="5-RJ" type="revolute">
				<pose>-0.10000000149011612 0.0 0.0 0.0 -0.0 0.0</pose>
				<parent>3-Core</parent>
				<child>2-wheel</child>
				<!-- WARNING: The SDF generator relies on annotations of the joint 5-RJ to specify in SDF aspects of the joint that are
					 accounted for in the equations. -->
			</joint>
			<!-- End of joints of the pmodel Base -->
			
			<!-- Start of fixed connections of the pmodel Base -->
			<!-- fixed joint full name is Base::Core::fixedJoint::Base::LWHEEL::wheel from Base::Core to Base::LWHEEL::wheel -->
			<joint name="6-fixedJoint" type="fixed">
				<parent>3-Core</parent>
				<child>1-wheel</child>
				<axis><xyz>0 0 1</xyz></axis>
			</joint>
			<!-- fixed joint full name is Base::Core::fixedJoint::Base::RWHEEL::wheel from Base::Core to Base::RWHEEL::wheel -->
			<joint name="7-fixedJoint" type="fixed">
				<parent>3-Core</parent>
				<child>2-wheel</child>
				<axis><xyz>0 0 1</xyz></axis>
			</joint>
			<!-- End of fixed connections of the pmodel Base -->
		</model>
</sdf>
